Workbook

Sheet Summary
B1: Rental Income and Expenses | H1: Investments
A2: Property Address | B2: 3305 N. Huson | E2: 91 Alder Ct | F2: 6621 4th St NE | H2: Tax Parcell 0121115002 | J2: VMN Holdings
B3: Tacoma | E3: Milton | F3: Fife | H3: Toderashko, Maksim and Maria
A4: Income | B4: 1099-MISC | C4: Pmt-checks | E4: Pmt-deposits | F4: Pmt-deposits | G4: Total | H4: Orig. Fee | I4: Interest | J4: Orig. Fee | K4: Interest
A5: 45292 | B5: 507 | C5: 2000 | D5: =SUM(B5:C5) -> 2507 | E5: 2500 | F5: 2500 | I5: 1250
A6: 45323 | B6: 577 | C6: 1458 | D6: =SUM(B6:C6) -> 2035 | E6: 2500 | F6: 2500 | I6: 1250
A7: 45352 | B7: 542 | C7: 1458 | D7: =SUM(B7:C7) -> 2000 | E7: 2500 | F7: 2500 | I7: 1250
A8: 45383 | B8: 542 | C8: 1458 | D8: =SUM(B8:C8) -> 2000 | E8: 2500 | F8: 2500 | I8: 1250
A9: 45413 | B9: 542 | C9: 1458 | D9: =SUM(B9:C9) -> 2000 | E9: 2500 | F9: 2500 | I9: 1250
A10: 45444 | B10: 542 | C10: 1458 | D10: =SUM(B10:C10) -> 2000 | E10: 2500 | F10: 2500 | I10: 1250
A11: 45474 | B11: 542 | C11: 1458 | D11: =SUM(B11:C11) -> 2000 | E11: 2500 | F11: 2500 | I11: 1250
A12: 45505 | B12: 542 | C12: 1458 | D12: =SUM(B12:C12) -> 2000 | E12: 2500 | F12: 2500 | I12: 1250
A13: 45536 | B13: 542 | C13: 1458 | D13: =SUM(B13:C13) -> 2000 | E13: 2500 | F13: 2500 | I13: 1250
A14: 45566 | B14: 542 | C14: 1458 | D14: =SUM(B14:C14) -> 2000 | E14: 3000 | F14: 3000 | I14: 1250
A15: 45597 | B15: 542 | C15: 1458 | D15: =SUM(B15:C15) -> 2000 | E15: 3000 | F15: 3000 | I15: 1767.12 | J15: 0
A16: 45627 | B16: 542 | C16: 1458 | D16: =SUM(B16:C16) -> 2000 | E16: 3000 | F16: 3000 | K16: 1500
A17: Total | B17: =SUM(B5:B16) -> 6504 | C17: =SUM(C5:C16) -> 18038 | D17: =SUM(D5:D16) -> 24542 | E17: =SUM(E5:E16) -> 31500 | F17: =SUM(F5:F16) -> 31500 | G17: =D17+E17+F17 -> 87542 | H17: =SUM(H5:H16) -> 0 | I17: =SUM(I5:I16) -> 14267.12 | J17: =SUM(J5:J16) -> 0 | K17: =SUM(K5:K16) -> 1500
A19: EXPENSES
A20: Advertising | C20: =Tacoma!G3 -> 0 | E20: =Milton!H3 -> 0 | F20: =Fife!G4 -> 0 | G20: =SUM(B20:F20) -> 0
A21: Association Dues | C21: =Tacoma!G4 -> 0 | E21: =Milton!H4 -> 0 | F21: =Fife!G5 -> 0 | G21: =SUM(B21:F21) -> 0
A22: Auto and Travel | C22: =Tacoma!G5 -> 0 | E22: =Milton!H5 -> 0 | F22: =Fife!G6 -> 0 | G22: =SUM(B22:F22) -> 0
A23: Cleaning and Maintenance | C23: =Tacoma!G6 -> 402.01 | E23: =Milton!H6 -> 124.36 | F23: =Fife!G7 -> 0 | G23: =SUM(B23:F23) -> 526.37
A24: Commissions | C24: =Tacoma!G7 -> 0 | E24: =Milton!H7 -> 0 | F24: =Fife!G8 -> 0 | G24: =SUM(B24:F24) -> 0
A25: Gardening | C25: =Tacoma!G8 -> 0 | E25: =Milton!H8 -> 236.24 | F25: =Fife!G9 -> 581.85 | G25: =SUM(B25:F25) -> 818.09
A26: Insurance | C26: =Tacoma!G9 -> 895.78 | E26: =Milton!H9 -> 982.94 | F26: =Fife!G10 -> 1206.74 | G26: =SUM(B26:F26) -> 3085.46
A27: Legal and Proffessional Fees | C27: =Tacoma!G10 -> 0 | E27: =Milton!H10 -> 0 | F27: =Fife!G11 -> 0 | G27: =SUM(B27:F27) -> 0
A28: Licenses and Permits | C28: =Tacoma!G11 -> 0 | E28: =Milton!H11 -> 0 | F28: =Fife!G12 -> 190 | G28: =SUM(B28:F28) -> 190
A29: Management fees | C29: =Tacoma!G12 -> 0 | E29: =Milton!H12 -> 0 | F29: =Fife!G13 -> 0 | G29: =SUM(B29:F29) -> 0
A30: Miscellaneous | C30: =Tacoma!G13 -> 0 | E30: =Milton!H13 -> 0 | F30: =Fife!G14 -> 0 | G30: =SUM(B30:F30) -> 0
A31: Mortgage Interest | C31: =Tacoma!G14 -> 3747.53 | E31: =Milton!H14 -> 2986.61 | F31: =Fife!G15 -> 9948.71 | G31: =SUM(B31:F31) -> 16682.85
... A42: Wages and Salaries | C42: =Tacoma!G25 -> 0 | E42: =Milton!H25 -> 0 | F42: =Fife!G26 -> 0 | G42: =SUM(B42:F42) -> 0
A43: Other | C43: =Tacoma!G26 -> 0 | F43: =Fife!G27 -> 105.06
A44: Microwave | E44: =Milton!H27 -> 2642.38
A45: Total Expenses | C45: =SUM(C20:C43) -> 14938.25 | D45: =SUM(D20:D43) -> 0 | E45: =SUM(E20:E44) -> 19490.14 | F45: =SUM(F20:F43) -> 35464.74 | G45: =SUM(G20:G43) -> 67145.69

Sheet Cabin
A1: Cabin
A2: Interest | B2: =13094.35+2569.2 -> 15663.55
A3: Taxes

Sheet Milton
A1: 91 Alder Ct Milton
A2: Date | B2: Business Name | C2: Category | D2: Amount
A3: 45632 | B3: Harbor Freight | C3: Cleaning and Maintenance | D3: 89.45 | G3: Advertising
A4: 45635 | B4: Harbor Freight | C4: Cleaning and Maintenance | D4: 34.91 | G4: Association Dues
A5: 45380 | B5: Costco | C5: Gardening | D5: 33.99 | G5: Auto and Travel
A6: 45491 | B6: Charboneau Excavation | C6: Gardening | D6: 108.35 | G6: Cleaning and Maintenance | H6: =SUM(D3:D4) -> 124.36
A7: 45544 | B7: Peninsula Topsoil | C7: Gardening | D7: 93.9 | G7: Commissions
A8: 45471 | B8: Albert Lee | C8: Other | D8: 2642.38 | E8: Microwave | G8: Gardening | H8: =SUM(D5:D7) -> 236.24
A9: 45463 | B9: Lowe's Home Centers | C9: Painting and Decorating | D9: 12.75 | G9: Insurance | H9: 982.94
A10: 45411 | B10: The Home Depot | C10: Painting and Decorating | D10: 17.62 | G10: Legal and Proffessional Fees
A11: 45520 | B11: Rodda Paint | C11: Painting and Decorating | D11: 139.64 | G11: Licenses and Permits
B12: Purcor | C12: Pest Control | D12: 159.87 | G12: Management fees
A13: 45299 | B13: The Home Depot | C13: Plubing and Electrical | D13: 36.08 | G13: Miscellaneous
A14: 45561 | B14: Olivers Liquidation | C14: Repairs | D14: 62.87 | G14: Mortgage Interest | H14: 2986.61
A15: 45475 | B15: Harbor Freight | C15: Repairs | D15: 115.66 | G15: Excess Mortgage Interest
A16: 45315 | B16: The Home Depot | C16: Repairs | D16: 208.73 | G16: Other interest (not entered elsewhere)
A17: 45319 | B17: The Home Depot | C17: Repairs | D17: 19.57 | G17: Painting and Decorating | H17: =SUM(D9:D11) -> 170.01
A18: 45321 | B18: The Home Depot | C18: Repairs | D18: 87.72 | G18: Pest Control | H18: =D12 -> 159.87
A19: 45334 | B19: The Home Depot | C19: Repairs | D19: 703.08 | G19: Plumbing and Electrical | H19: =D13 -> 36.08
A20: 45322 | B20: The Home Depot | C20: Repairs | D20: 16.6 | G20: Repairs | H20: =SUM(D14:D27) -> 6926.95
A21: 45446 | B21: Willco | C21: Repairs | D21: 17.28 | G21: Supplies
A22: 45357 | B22: Jet Door Moto | C22: Repairs | D22: 3507.23 | E22: Door Replacements | G22: Taxes - Real Estate | H22: 5224.7
A23: 45359 | B23: Builders FirstSource | C23: Repairs | D23: 23.73 | G23: Taxes - Other (not entered eleswhere)
A24: 45350 | B24: Jet Door Moto | C24: Repairs | D24: 201.95 | E24: Door Trim Replacement | G24: Telephone
A25: 45350 | B25: Jet Door Moto | C25: Repairs | D25: 1510.34 | E25: Door Replacements | G25: Wages and Salaries
A26: 45554 | B26: Variety Roofing and Construction | C26: Repairs | D26: 424.66 | G26: Other
A27: 45295 | B27: Cash America | C27: Repairs | D27: 27.53 | G27: Microwave | H27: =D8 -> 2642.38 | I27: Microwave
H28: =SUM(H3:H27) -> 19490.14

Sheet Fife
A1: 6221 4th ST NE Tacoma WA
A2: Date | B2: Business Name | C2: Category | D2: Amount | E2: Notes
A3: 45399 | B3: Batteries Plus | C3: Gardening | D3: 204.04
A4: 45618 | B4: O'Reilly | C4: Gardening | D4: 5.29 | F4: Advertising
A5: 45415 | B5: Sterino Farms Produce Market | C5: Gardening | D5: 50 | F5: Association Dues
A6: 45415 | B6: Sterino Farms Produce Market | C6: Gardening | D6: 44.04 | F6: Auto and Travel
A7: 45385 | B7: The Home Depot | C7: Gardening | D7: 40.42 | F7: Cleaning and Maintenance
A8: 45397 | B8: Purty Topsoil | C8: Gardening | D8: 119.03 | F8: Commissions
A9: 45398 | B9: Purty Topsoil | C9: Gardening | D9: 119.03 | F9: Gardening | G9: =SUM(D3:D9) -> 581.85
A10: 45489 | B10: Purty Transerfer Station | C10: Other- Repair Trash Disp | D10: 57.96 | F10: Insurance | G10: 1206.74
A11: 45483 | B11: Purty Transerfer Station | C11: Other- Repair Trash Disp | D11: 47.1 | F11: Legal and Proffessional Fees
A12: 45464 | B12: Costco | C12: Painting and Decorating | D12: 79.99 | F12: Licenses and Permits | G12: 190
A13: 45562 | B13: Costco | C13: Painting and Decorating | D13: 99.97 | F13: Management fees
A14: 45348 | B14: Harbor Freight | C14: Painting and Decorating | D14: 22.04 | F14: Miscellaneous
A15: 45553 | B15: The Home Depot | C15: Painting and Decorating | D15: 11.73 | F15: Mortgage Interest | G15: 9948.71
A16: 45405 | B16: Mutual Materials | C16: Painting and Decorating | D16: 222.32 | F16: Excess Mortgage Interest
A17: 45411 | B17: Mutual Materials | C17: Painting and Decorating | D17: 114.11 | F17: Other interest (not entered elsewhere)
B18: Bolton Insulation | C18: Plumbing and Electrical | D18: 7852.38 | F18: Painting and Decorating | G18: =SUM(D12:D31) -> 11565.19
A19: 45392 | B19: Ace Hardware | C19: Plumbing and Electrical | D19: 29.17 | F19: Pest Control
A20: 45558 | B20: Capital Lumber & Door | C20: Plumbing and Electrical | D20: 30.87 | F20: Plumbing and Electrical
A21: 45295 | B21: Olivers Liquidation | C21: Plumbing and Electrical | D21: 49.59 | F21: Repairs | G21: =SUM(D32:D49) -> 4490.48
A22: 45317 | B22: Lowe's Home Centers | C22: Plumbing and Electrical | D22: 122.11 | F22: Supplies | G22: =SUM(D50) -> 12.72
A23: 45383 | B23: The Home Depot | C23: Plumbing and Electrical | D23: 118.76 | F23: Taxes - Real Estate | G23: 7363.99
A24: 45321 | B24: FloHawks Pluming Services | C24: Plumbing and Electrical | D24: 375.11 | F24: Taxes - Other (not entered eleswhere)
A25: 45621 | B25: Grainger | C25: Plumbing and Electrical | D25: 3.11 | F25: Telephone
A26: 45625 | B26: Grainger | C26: Plumbing and Electrical | D26: 10.46 | F26: Wages and Salaries
A27: 45628 | B27: Grainger | C27: Plumbing and Electrical | D27: 4.2 | F27: Other | G27: =SUM(D10:D11) -> 105.06
A28: 45314 | B28: G&N Septic Tank | C28: Plumbing and Electrical | D28: 308.28 | F28: List
A29: 45616 | B29: A Advanced Services | C29: Plumbing and Electrical | D29: 271.4 | G29: =SUM(G4:G28) -> 35464.74
A30: 45617 | B30: Sterling Septic and Plumbing | C30: Plumbing and Electrical | D30: 1641.59
A31: 45657 | B31: Hunt's Plumbing (Total) | C31: Plumbing and Electrical | D31: =16.5*12 -> 198 | E31: $16.50 X 12
A32: 45350 | B32: Floor and Décor | C32: Repairs | D32: 35.14
A33: 45399 | B33: Floor and Décor | C33: Repairs | D33: 13.12
A34: 45463 | B34: Floor and Décor | C34: Repairs | D34: 7.5
A35: 45467 | B35: Floor and Décor | C35: Repairs | D35: 189.08
A36: 45573 | B36: Capital Lumber & Door | C36: Repairs | D36: 1.29
A37: 45358 | B37: Harbor Freight | C37: Repairs | D37: 276.05
A38: 01/0524 | B38: Lowe's Home Centers | C38: Repairs | D38: 14.72
A39: 45376 | B39: The Home Depot | C39: Repairs | D39: 113.67
A40: 45359 | B40: The Home Depot | C40: Repairs | D40: 142.99
...

Sheet Tacoma
A1: 3305 N Huson ST Tacoma
A2: Date | B2: Business Name | C2: Category | D2: Amount
A3: 45446 | B3: Harbor Freight | C3: Cleaning and Mainenance | D3: 7.71 | F3: Advertising
A4: 45446 | B4: Harbor Freight | C4: Cleaning and Mainenance | D4: 25.36 | F4: Association Dues
A5: 45452 | B5: Harbor Freight | C5: Cleaning and Mainenance | D5: 368.94 | F5: Auto and Travel
A6: 45386 | B6: Capital Lumber | C6: Plumbing and Electrical | D6: 25.93 | F6: Cleaning and Maintenance | G6: =SUM(D3:D5) -> 402.01
A7: 45393 | B7: Capital Lumber | C7: Plumbing and Electrical | D7: 29.42 | F7: Commissions
A8: 45383 | B8: Lowe's Home Centers | C8: Plumbing and Electrical | D8: 20.14 | F8: Gardening
A9: 45385 | B9: Lowe's Home Centers | C9: Plumbing and Electrical | D9: 25.61 | F9: Insurance | G9: 895.78
A10: 45392 | B10: The Home Depot | C10: Plumbing and Electrical | D10: 1087.85 | F10: Legal and Proffessional Fees
A11: 45293 | B11: Scott McLendon's | C11: Plumbing and Electrical | D11: 62.68 | F11: Licenses and Permits
A12: 45401 | B12: Scott McLendon's | C12: Plumbing and Electrical | D12: 5.99 | F12: Management fees
A13: 1/2/224 | B13: Capital Lumber | C13: Repairs | D13: 2.61 | F13: Miscellaneous
A14: 45377 | B14: Capital Lumber | C14: Repairs | D14: 7.26 | F14: Mortgage Interest | G14: 3747.53
A15: 45343 | B15: Olivers Liquidation | C15: Repairs | D15: 55.1 | F15: Excess Mortgage Interest
A16: 45446 | B16: Harbor Freight | C16: Repairs | D16: 60.6 | F16: Other interest (not entered elsewhere)
A17: 45355 | B17: The Home Depot | C17: Repairs | D17: 67.65 | F17: Painting and Decorating
A18: 45401 | B18: The Home Depot | C18: Repairs | D18: 110.14 | F18: Pest Control
A19: 45388 | B19: The Home Depot | C19: Repairs | D19: 14.67 | F19: Plumbing and Electrical | G19: =SUM(D6:D12) -> 1257.62
A20: 45645 | B20: The Home Depot | C20: Repairs | D20: 12.71 | F20: Repairs | G20: =SUM(D13:D22) -> 2931.23
A21: 45526 | B21: Peninsula Topsoil | C21: Repairs | D21: 1267.71 | E21: Road | F21: Supplies
A22: 45527 | B22: Peninsula Topsoil | C22: Repairs | D22: 1332.78 | E22: Road | F22: Taxes - Real Estate | G22: 5704.08
F23: Taxes - Other (not entered eleswhere)
F24: Telephone
F25: Wages and Salaries
F26: Other
F27: List
F28: Total | G28: =SUM(G3:G27) -> 14938.25
